<mujoco model="Robot">
    <compiler angle="radian"/>
    <option timestep="0.01"/>
    <asset>
        <texture type="skybox" builtin="none" file="../textures/skybox.png" gridsize = "3 4" gridlayout = ".U..LFRB.D.." rgb1=".2 .62 .9" rgb2="0 0 0"/>
        <material name="robot_texture" rgba="0.700 0.700 0.700 1.000"/>
        <texture name="grid" type="2d" builtin="checker" width="512" height="512" rgb1=".1 .2 .3" rgb2=".2 .3 .4"/>
        <material name="grid" texture="grid" texrepeat="1 1" texuniform="true" reflectance=".2"/>

        <mesh name="base_link" file="../meshes/base_link.stl" scale="0.001 0.001 0.001"/>
        <mesh name="r_upper_hip" file="../meshes/r_upper_hip.stl" scale="0.001 0.001 0.001"/>
        <mesh name="r_hip" file="../meshes/r_hip.stl" scale="0.001 0.001 0.001"/>
        <mesh name="r_upper_leg" file="../meshes/r_upper_leg.stl" scale="0.001 0.001 0.001"/>
        <mesh name="r_lower_leg" file="../meshes/r_lower_leg.stl" scale="0.001 0.001 0.001"/>
        <mesh name="r_ankle" file="../meshes/r_ankle.stl" scale="0.001 0.001 0.001"/>
        <mesh name="r_foot" file="../meshes/r_foot.stl" scale="0.001 0.001 0.001"/>
        <mesh name="l_upper_hip" file="../meshes/l_upper_hip.stl" scale="0.001 0.001 0.001"/>
        <mesh name="l_lower_hip" file="../meshes/l_lower_hip.stl" scale="0.001 0.001 0.001"/>
        <mesh name="l_upper_leg" file="../meshes/l_upper_leg.stl" scale="0.001 0.001 0.001"/>
        <mesh name="l_lower_leg" file="../meshes/l_lower_leg.stl" scale="0.001 0.001 0.001"/>
        <mesh name="l_ankle" file="../meshes/l_ankle.stl" scale="0.001 0.001 0.001"/>
        <mesh name="l_foot" file="../meshes/l_foot.stl" scale="0.001 0.001 0.001"/>
        <mesh name="l_hip_motor" file="../meshes/l_hip_motor.stl" scale="0.001 0.001 0.001"/>
        <mesh name="r_hip_motor" file="../meshes/r_hip_motor.stl" scale="0.001 0.001 0.001"/>
        <mesh name="board_simplified_1" file="../meshes/board_simplified_1.stl" scale="0.001 0.001 0.001"/>
    </asset>

    <default>
        <geom type="mesh" solref=".004 1"/>
        <joint damping="1.084" armature="0.045" frictionloss="0.03" actuatorfrcrange="-100 100"/>
        <position kp="21.1" ctrlrange="-3.141592 3.141592" forcerange="-5 5"/>
        <default class="visual">
            <geom material="robot_texture"/>
        </default>
    </default>

    <worldbody>
        <geom name="floor" size="0 0 .05" type="plane" material="grid" condim="3"/>
        <light name="spotlight" mode="targetbodycom" target="torso" diffuse=".8 .8 .8" specular="0.3 0.3 0.3" pos="0 -6 4" cutoff="30"/>
        
        <body name="torso" pos="0 0 0">
            <light name="top" pos="0 0 2" mode="trackcom"/>
            <camera name="back" pos="-3 0 1" xyaxes="0 -1 0 1 0 2" mode="trackcom"/>
            <camera name="side" pos="0 -3 1" xyaxes="1 0 0 0 1 2" mode="trackcom"/>
            <freejoint name="root"/>
            <geom name="torso" type="mesh" mesh="base_link" class="visual"/>
            <geom type="mesh" mesh="l_hip_motor" class="visual"/>
            <geom type="mesh" mesh="r_hip_motor" class="visual"/>
            <geom type="mesh" mesh="board_simplified_1" class="visual"/>
            <body name="l_upper_hip" pos="-0.0005 0.037352 0.334234">
                <inertial pos="-0.00694059 -9.1299e-08 -0.0485837" quat="0.70116 -0.0915155 -0.0915155 0.70116" mass="0.0295176" diaginertia="3.8e-05 2.80623e-05 1.19377e-05"/>
                <joint name="r_hip_z" pos="0 0 0" axis="0 0 1" range="-1.5708 0.698132"/>
                <geom pos="0.0005 -0.037352 -0.334234" quat="1 0 0 0" type="mesh" mesh="l_upper_hip" class="visual"/>
                <body name="l_lower_hip" pos="0.0235 0 -0.083">
                    <inertial pos="-0.0234498 0.0107536 -0.00459196" quat="0.771073 0.636747 0 0" mass="0.111904" diaginertia="3.7e-05 3.61926e-05 3.08074e-05"/>
                    <joint name="r_hip_y" pos="0 0 0" axis="1 0 0" range="-1.5708 0.785398"/>
                    <geom pos="-0.023 -0.037352 -0.251234" quat="1 0 0 0" type="mesh" mesh="l_lower_hip" class="visual"/>
                    <body name="l_upper_leg" pos="-0.023477 -0.013383 -0.039959">
                    <inertial pos="5.1192e-06 0.0236078 -0.0172742" mass="0.111651" diaginertia="6.2e-05 4.2e-05 2.7e-05"/>
                    <joint name="r_hip_x" pos="0 0 0" axis="0 1 0" range="-2.00713 2.00713"/>
                    <geom pos="0.000477 -0.023969 -0.211275" type="mesh" mesh="l_upper_leg" class="visual"/>
                    <body name="l_lower_leg" pos="1.5e-05 0.000432 -0.063998">
                        <inertial pos="3.84448e-06 0.0235546 -0.0371166" mass="0.192145" diaginertia="0.000184 0.000161 3.6e-05"/>
                        <joint name="r_knee" pos="0 0 0" axis="0 1 0" range="-2.35619 2.35619"/>
                        <geom pos="0.000462 -0.024401 -0.147277" type="mesh" mesh="l_lower_leg" class="visual"/>
                        <body name="l_ankle" pos="0 -0.0015 -0.074233">
                        <inertial pos="7.31829e-08 0.0200002 -0.0250003" quat="0.310076 0.635494 -0.635494 0.310076" mass="0.0316626" diaginertia="2.05616e-05 1.9e-05 1.64384e-05"/>
                        <joint name="r_ankle_y" pos="0 0 0" axis="0 1 0" range="-1.91986 1.91986"/>
                        <geom pos="0.000462 -0.022901 -0.073044" quat="1 0 0 0" type="mesh" mesh="l_ankle" class="visual"/>
                        <body name="l_foot" pos="0.0235 0.015 -0.05">
                            <inertial pos="-0.0213185 0.0101746 -0.00821998" quat="0 0.761637 0 0.648004" mass="0.157381" diaginertia="7.26491e-05 6e-05 4.73509e-05"/>
                            <joint name="r_ankle_x" pos="0 0 0" axis="1 0 0" range="-1.5708 0.436332"/>
                            <geom pos="-0.023038 -0.037901 -0.023044" quat="1 0 0 0" type="mesh" mesh="l_foot" class="visual"/>
                        </body>
                        </body>
                    </body>
                    </body>
                </body>
            </body>
            <body name="r_upper_hip" pos="-0.0006 -0.037165 0.335135">
                <inertial pos="-0.00694083 3.3037e-07 -0.0485836" quat="0.70116 -0.0915155 -0.0915155 0.70116" mass="0.0295176" diaginertia="3.8e-05 2.80623e-05 1.19377e-05"/>
                <joint name="l_hip_z" pos="0 0 0" axis="0 0 1" range="-0.698132 1.5708"/>
                <geom pos="0.0006 0.037165 -0.335135" quat="1 0 0 0" type="mesh" mesh="r_upper_hip" class="visual"/>
                <body name="r_hip" pos="0.0235 0 -0.083">
                    <inertial pos="-0.0234501 -0.0107534 -0.00459179" quat="0.636747 0.771073 0 0" mass="0.111904" diaginertia="3.7e-05 3.61926e-05 3.08074e-05"/>
                    <joint name="l_hip_y" pos="0 0 0" axis="1 0 0" range="-0.785398 1.5708"/>
                    <geom pos="-0.0229 0.037165 -0.252135" quat="1 0 0 0" type="mesh" mesh="r_hip" class="visual"/>
                    <body name="r_upper_leg" pos="-0.023477 0.013384 -0.039959">
                    <inertial pos="4.88398e-06 -0.0236086 -0.017274" mass="0.111651" diaginertia="6.2e-05 4.2e-05 2.7e-05"/>
                    <joint name="l_hip_x" pos="0 0 0" axis="0 1 0" range="-2.00713 2.00713"/>
                    <geom pos="0.000577 0.023781 -0.212176" type="mesh" mesh="r_upper_leg" class="visual"/>
                    <body name="r_lower_leg" pos="1.5e-05 -0.000433 -0.063998">
                        <inertial pos="3.60925e-06 -0.0235544 -0.0371164" mass="0.192145" diaginertia="0.000184 0.000161 3.6e-05"/>
                        <joint name="l_knee" pos="0 0 0" axis="0 1 0" range="-2.26893 2.35619"/>
                        <geom pos="0.000562 0.024214 -0.148178" type="mesh" mesh="r_lower_leg" class="visual"/>
                        <body name="r_ankle" pos="0 0.0015 -0.074233">
                        <inertial pos="-1.6372e-07 -0.0199999 -0.0250001" quat="0.635494 0.310076 -0.310076 0.635494" mass="0.0316626" diaginertia="2.05616e-05 1.9e-05 1.64384e-05"/>
                        <joint name="l_ankle_y" pos="0 0 0" axis="0 1 0" range="-1.91986 1.91986"/>
                        <geom pos="0.000562 0.022714 -0.073945" quat="1 0 0 0" type="mesh" mesh="r_ankle" class="visual"/>
                        <body name="r_foot" pos="0.0235 -0.015 -0.05">
                            <inertial pos="-0.0213188 -0.0100895 -0.00821981" quat="0.0202379 0.761052 0.0335931 0.647504" mass="0.157381" diaginertia="7.27257e-05 5.99255e-05 4.73489e-05"/>
                            <joint name="l_ankle_x" pos="0 0 0" axis="1 0 0" range="-0.436332 1.5708"/>
                            <geom pos="-0.022938 0.037714 -0.023945" quat="1 0 0 0" type="mesh" mesh="r_foot" class="visual"/>
                        </body>
                        </body>
                    </body>
                    </body>
                </body>
            </body>
        </body>
        
    </worldbody>

    <actuator>
        <position name="r_hip_z"     joint="r_hip_z"  />
        <position name="r_hip_x"     joint="r_hip_x"  />
        <position name="r_hip_y"     joint="r_hip_y"  />
        <position name="r_knee"      joint="r_knee"   />
        <position name="r_ankle_y"   joint="r_ankle_y"/>
        <position name="r_ankle_x"   joint="r_ankle_x"/>
        <position name="l_hip_z"     joint="l_hip_z"  />
        <position name="l_hip_x"     joint="l_hip_x"  />
        <position name="l_hip_y"     joint="l_hip_y"  />
        <position name="l_knee"      joint="l_knee"   />
        <position name="l_ankle_y"   joint="l_ankle_y"/>
        <position name="l_ankle_x"   joint="l_ankle_x"/>
    </actuator>

</mujoco>
